Workbook

Sheet Instructions
A1: DEBMM Assessment Tool
A2: Detection Engineering Behavior Maturity Model — Audit Assessment
B4: About This Assessment
B5: This spreadsheet assesses your detection engineering team's maturity using Elastic's Detection Engineering Behavior Maturity Model (DEBMM), enriched with organizational dimensions from detectionengineering.io.
B7: It covers 21 criteria across 7 categories, with 41 dropdown questions total.
B8: All questions use dropdowns (Yes/No or Scale 1—5). No free-text required.
B10: How to Use
B11: 1. Go to the Assessment tab and fill in your organization details
B12: 2. Answer each question using the dropdown menus in the amber column
B13: 3. For Yes/No questions — select from the dropdown
B14: 4. For Scale questions (1—5) — select your maturity rating
B15: 5. Switch to the Results Dashboard tab to see scores calculated automatically
B17: Understanding the Model
B18: DEBMM Core Tiers (Elastic) | C18: Supplementary Dimensions
B19: Tier 0 — Foundation | C19: People & Organization
B20: Rule development, maintenance, roadmaps, threat modeling | C20: Team structure, training, leadership
B21: Tier 1 — Basic | C21: Process & Governance
B22: Baseline rules, telemetry, version control, testing | C22: Lifecycle, metrics, collaboration
B23: Tier 2 — Intermediate
B24: FP reduction, gap analysis, internal validation | C24: These supplementary dimensions assess
B25: Tier 3 — Advanced | C25: organizational readiness. They contribute
B26: FN triage, external validation, advanced TTP coverage | C26: to the overall score but do not affect
B27: Tier 4 — Expert | C27: DEBMM tier determination.
B28: Threat hunting, automation, AI/LLM integration
B30: Maturity Levels
B31: Each criterion is scored on a 1—5 scale:
B33: 1 — Initial Minimal or no structured activity
B34: 2 — Repeatable Sporadic, inconsistent efforts
B35: 3 — Defined Regular, documented processes followed consistently
B36: 4 — Managed Comprehensive, well-integrated with measurable outcomes
B37: 5 — Optimized Fully automated, continuously improving
B39: Tier Determination
B40: Your achieved tier is the highest tier where ALL criteria in that tier (and all lower tiers) score ≥ 3.0 (Defined level). This enforces the progressive nature of the model — you need solid foundations before claiming advanced maturity.
B42: Enrichment dimensions (People & Organization, Process & Governance) contribute to the overall maturity score but are not part of the tier determination logic.
B44: Scoring Paths
... B52: MITRE ATT&CK: https://attack.mitre.org/

Sheet Assessment
A1: DEBMM Assessment
A2: Detection Engineering Behavior Maturity Model
C4: Organization:
C5: Assessor Name:
C6: Assessor Role:
C7: Date:
C8: Assessment Type: | D8: Audit
B10: DEBMM CORE ASSESSMENT — Tiers 0—4
B11: Rate your team across the 5 progressive DEBMM tiers. Your achieved tier is the highest where all criteria score ≥ 3.0.
B12: ID | C12: Criterion | D12: Question | E12: Answer | F12: Score | G12: Evidence / Notes
B13: TIER 0: FOUNDATION
B14: Establishes the basic groundwork for detection engineering.
B15: T0-Q1 | C15: Structured Rule Development Approach | D15: Rate the maturity of the assessed team's rule development process. 1 — No structured approach; rules created ad hoc or reactively (0% follow a formal process) 2 — Some rules follow a loose process but it is inconsistently applied (<30% follow a documented process) 3 — Defined methodology is documented and followed for most new rules (50-70% follow process; schema alignment >60%) 4 — Standardized across team with enforced workflows, templates, and quality gates (80-90% schema alignment; all new rules go through formal review) 5 — Continuous improvement via feedback loops; fully integrated with CI/CD and automated linting/validation (90-100% schema alignment) | F15: =IF(E15="","",E15)
B16: T0-Q2 | C16: Structured Rule Development Approach | D16: Do all new detection rules go through peer review before production deployment? | F16: =IF(E16="Yes",4,IF(E16="No",1,""))
B17: T0-Q3 | C17: Rule Creation and Maintenance | D17: What percentage of the assessed team's rules are reviewed on a regular schedule? 1 — Less than 50% reviewed annually; no rule owners assigned 2 — 50-70% reviewed annually; rules may have informal owners but no formal peer review process 3 — 70-80% reviewed on schedule; rules have assigned owners and defined review cycles; peer review on most changes 4 — 80-90% reviewed on schedule; comprehensive lifecycle management (create, test, deploy, monitor, retire); 100% peer review on changes 5 — 90-100% reviewed on schedule; automated rule health monitoring flags stale or broken rules for review | F17: =IF(E17="","",E17)
B18: T0-Q4 | C18: Roadmap Documentation | D18: Rate the maturity of the assessed team's detection engineering roadmap. 1 — No roadmap exists; work is entirely reactive or driven by individual initiative 2 — Informal roadmap or backlog exists (e.g., a Jira board or wiki page) but is not regularly maintained or shared (<30% of work tied to a plan) 3 — Formal roadmap documented, reviewed at least quarterly, shared with stakeholders; priorities are clear (50-70% of planned work tracked) 4 — Integrated with organizational security strategy; progress tracked with metrics and reported to leadership (70-90% tracked; quarterly leadership reviews) 5 — Dynamic, continuously updated roadmap driven by threat intel, gap analysis, and risk priorities (90-100% tracked; auto-updated from analysis feeds) | F18: =IF(E18="","",E18)
B19: T0-Q5 | C19: Threat Modeling | D19: How frequently does the assessed team perform threat modeling? 1 — Never performed or not at all 2 — Less than once per year; typically triggered by a major incident or audit finding 3 — 1-2 times per year with documented results that inform the detection roadmap 4 — Quarterly or more; outputs directly prioritize new detection development (>70% of new detections tied to threat model outputs) 5 — Continuous proactive modeling incorporating real-time threat intel, attack surface changes, and emerging TTPs | F19: =IF(E19="","",E19)
B20: T0-Q6 | C20: Threat Modeling | D20: Does the assessed team's threat modeling use a recognized framework? | F20: =IF(E20="Yes",3,IF(E20="No",1,""))
B21: T0-Q7 | C21: Threat Modeling | D21: Do threat modeling outputs directly generate items on the assessed team's backlog? | F21: =IF(E21="Yes",4,IF(E21="No",1,""))
B22: TIER 1: BASIC
B23: Establishes baseline detection capabilities with systematic management, version control, and initial alignment with the threat landscape.
B24: T1-Q1 | C24: Baseline Rule Creation | D24: How many custom detection rules does the assessed team maintain? 1 — Fewer than 10 custom rules; mostly relying on vendor/out-of-the-box rules 2 — 10-30 rules covering the most critical threats (e.g., ransomware, credential theft, C2) 3 — 30-60 rules with a mix of signature-based and behavioral detections across major categories 4 — 60-100 rules including behavioral and TTP-focused detections tuned per environment 5 — 100+ rules with continuous refinement, environment-specific tuning, and automated coverage analysis | F24: =IF(E24="","",E24)
B25: T1-Q2 | C25: Baseline Rule Creation | D25: Estimate the assessed team's MITRE ATT&CK technique coverage for priority areas. 1 — Unknown or not measured; no ATT&CK mapping performed 2 — Less than 30% of priority techniques covered; coverage is ad hoc 3 — 30-50% of priority techniques covered with documented gaps identified 4 — 50-70% coverage including behavioral detections; gaps tracked against threat model 5 — Over 70% coverage with continuous gap analysis and automated coverage tracking | F25: =IF(E25="","",E25)
B26: T1-Q3 | C26: Ruleset Management and Maintenance | D26: Rate the maturity of the assessed team's ruleset management. 1 — No formal management; rules live only in the SIEM console with no version control or documentation (<20% in version control) 2 — Some rules stored in version control (e.g., Git) with basic documentation (20-50% in VCS) 3 — Most rules in version control with documentation standards; detection-as-code approach being adopted (50-80% in VCS with docs) 4 — Detection-as-code is standard practice; CI/CD pipelines handle rule testing and deployment; all rules documented and versioned (80-90% in DaC pipeline) 5 — Fully automated rule lifecycle: CI/CD, automated testing, continuous validation, and weekly maintenance cycles (100% DaC) | F26: =IF(E26="","",E26)
B27: T1-Q4 | C27: Telemetry Quality | D27: Rate the quality and coverage of the assessed team's telemetry. 1 — No active telemetry management; using whatever data sources happen to be available (<30% of rule types have adequate telemetry) 2 — Some awareness of gaps; basic health checks on critical sources like EDR and firewall logs (30-50% adequate coverage) 3 — Actively monitored; data source coverage mapped to detection needs; CTI enrichment beginning (50-70% coverage) 4 — Comprehensive with automated health monitoring, CTI enrichment, and proactive gap identification (70-90% coverage) 5 — Advanced workflows with real-time enrichment, automated remediation of telemetry gaps, full CTI integration (90-100% coverage) | F27: =IF(E27="","",E27)
B28: T1-Q5 | C28: Telemetry Quality | D28: Does the assessed team maintain a documented data source inventory mapped to use cases? | F28: =IF(E28="Yes",3,IF(E28="No",1,""))
B29: T1-Q6 | C29: Telemetry Quality | D29: Does the assessed team have automated alerting for data source degradation? | F29: =IF(E29="Yes",4,IF(E29="No",1,""))
B30: T1-Q7 | C30: Threat Landscape Review | D30: How frequently does the assessed team review the threat landscape? 1 — No regular reviews; detection priorities are not informed by current threats 2 — Annually or bi-annually; some rule updates after major threat advisories (1-2 reviews/year) 3 — Quarterly with documented findings that update the detection roadmap (50-70% of rules reviewed against current threats) 4 — Monthly reviews integrated with threat intelligence feeds; detection priorities continuously aligned (70-90% aligned) 5 — Real-time threat landscape monitoring with automated intel feeds driving detection priority updates (90-100% aligned) | F30: =IF(E30="","",E30)
B31: T1-Q8 | C31: Product Owner Engagement | D31: Rate the engagement between the assessed team and product/platform owners. 1 — No engagement; detection needs are never communicated to product/platform teams 2 — Occasional ad hoc engagement, typically reactive to issues or missing features (fewer than 4 interactions per year) 3 — Quarterly structured engagements to communicate detection needs, request features, and provide feedback 4 — Monthly proactive partnership; detection requirements tracked on product roadmaps (>50% of requests on roadmap) 5 — Continuous engagement with joint planning, shared success metrics, and detection needs directly influencing product development | F31: =IF(E31="","",E31)
B32: T1-Q9 | C32: Release Testing and Validation | D32: Rate the maturity of the assessed team's release testing. 1 — No testing; rules are deployed to production without validation (<20% tested) 2 — Basic manual testing on some rules before deployment; no standardized process or test environment (20-40% tested) 3 — Standardized testing with defined test cases and a staging/test environment; most rules validated before deploy (50-70% tested) 4 — Comprehensive testing including unit tests, integration tests, and emulation-based validation; rapid deployment for emerging threats (70-90% automated; 24hr critical deployment capability) 5 — Continuous automated testing in full CI/CD pipeline; every rule validated before every deployment (90-100% automated) | F32: =IF(E32="","",E32)
B33: TIER 2: INTERMEDIATE
B34: Focuses on improving detection quality through tuning, gap analysis, and systematic internal validation.
B35: T2-Q1 | C35: False Positive Tuning and Reduction | D35: Rate the maturity of the assessed team's FP reduction program. 1 — Minimal or no tuning; high false positive rates accepted as normal; no FP metrics tracked 2 — Reactive tuning when analysts complain about noisy rules; no systematic tracking of FP rates (10-25% FP reduction from baseline) 3 — Regular tuning cycles (at least quarterly); FP rates tracked per rule; tuning is documented (25-50% FP reduction) 4 — Comprehensive FP management with automated tuning suggestions, risk-based alert scoring, and continuous monitoring (>50% FP reduction) 5 — Automated dynamic tuning with ML; near-zero unnecessary alert noise; continuous optimization (>75% FP reduction from baseline) | F35: =IF(E35="","",E35)
B36: T2-Q2 | C36: False Positive Tuning and Reduction | D36: What is the assessed team's estimated FP reduction from baseline? 1 — Unknown or not measured 2 — Less than 25% reduction 3 — 25-50% reduction with per-rule FP rate tracking 4 — 50-75% reduction with automated tuning recommendations 5 — Over 75% reduction with ML-assisted continuous tuning | F36: =IF(E36="","",E36)
B37: T2-Q3 | C37: Gap Analysis and Documentation | D37: Rate the maturity of the assessed team's gap analysis. 1 — No gap analysis performed; detection coverage gaps are unknown 2 — Some gaps identified informally after incidents expose missing detections (1-3 gaps documented; reactive only) 3 — Regular analysis against ATT&CK or similar frameworks at least quarterly; gaps documented, prioritized, and tracked (5+ gaps documented and prioritized) 4 — Comprehensive analysis integrated with threat modeling and risk assessment; gaps drive the detection roadmap (continuous tracking; integrated into roadmap) 5 — Automated gap analysis using coverage mapping tools; real-time dashboards showing detection coverage (automated continuous analysis) | F37: =IF(E37="","",E37)
B38: T2-Q4 | C38: Gap Analysis and Documentation | D38: Does the assessed team maintain a documented, prioritized gap list updated quarterly? | F38: =IF(E38="Yes",3,IF(E38="No",1,""))
B39: T2-Q5 | C39: Gap Analysis and Documentation | D39: Are the assessed team's gaps communicated to stakeholders at least quarterly? | F39: =IF(E39="Yes",4,IF(E39="No",1,""))
B40: T2-Q6 | C40: Internal Testing and Validation | D40: Rate the maturity of the assessed team's internal testing program. 1 — No internal testing; rules are assumed to work once deployed 2 — Occasional manual testing of high-priority rules using basic atomic tests (<40% emulation coverage) 3 — Regular testing program with attack emulation (e.g., Atomic Red Team, Caldera) covering major detection categories; results documented (40-70% emulation coverage; at least quarterly) 4 — Comprehensive testing with automated attack emulation, purple team exercises, and continuous validation (70-90% automated emulation coverage) 5 — Continuous automated testing with full emulation coverage and automated regression testing on every rule change (>90% automated coverage) | F40: =IF(E40="","",E40)
B41: TIER 3: ADVANCED
B42: Addresses false negatives, external validation, and advanced threat coverage to ensure detections catch real attacks.
...

Sheet Results Dashboard
A1: DEBMM Assessment Results
A2: =" "&Assessment!D4
B5: Overall Maturity Score | D5: Achieved DEBMM Tier | F5: Completion
B6: =IF(COUNT(D13,D14,D15,D16,D18,D19,D20,D21,D22,D23,D25,D26,D27,D29,D30,D31,D33,D34,D40,D41,D42,D44,D45,D46)=0,"",ROUND(AVERAGE(D13,D14,D15,D16,D18,D19,D20,D21,D22,D23,D25,D26,D27,D29,D30,D31,D33,D34,D40,D41,D42,D44,D45,D46),2)&" / 5.0") | D6: =IF(AND(AND(ISNUMBER(D13),D13>=3,ISNUMBER(D14),D14>=3,ISNUMBER(D15),D15>=3,ISNUMBER(D16),D16>=3),AND(ISNUMBER(D18),D18>=3,ISNUMBER(D19),D19>=3,ISNUMBER(D20),D20>=3,ISNUMBER(D21),D21>=3,ISNUMBER(D22),D22>=3,ISNUMBER(D23),D23>=3),AND(ISNUMBER(D25),D25>=3,ISNUMBER(D26),D26>=3,ISNUMBER(D27),D27>=3),AND(ISNUMBER(D29),D29>=3,ISNUMBER(D30),D30>=3,ISNUMBER(D31),D31>=3),AND(ISNUMBER(D33),D33>=3,ISNUMBER(D34),D34>=3)),"Tier 4: Expert",IF(AND(AND(ISNUMBER(D13),D13>=3,ISNUMBER(D14),D14>=3,ISNUMBER(D15),D15>=3,ISNUMBER(D16),D16>=3),AND(ISNUMBER(D18),D18>=3,ISNUMBER(D19),D19>=3,ISNUMBER(D20),D20>=3,ISNUMBER(D21),D21>=3,ISNUMBER(D22),D22>=3,ISNUMBER(D23),D23>=3),AND(ISNUMBER(D25),D25>=3,ISNUMBER(D26),D26>=3,ISNUMBER(D27),D27>=3),AND(ISNUMBER(D29),D29>=3,ISNUMBER(D30),D30>=3,ISNUMBER(D31),D31>=3)),"Tier 3: Advanced",IF(AND(AND(ISNUMBER(D13),D13>=3,ISNUMBER(D14),D14>=3,ISNUMBER(D15),D15>=3,ISNUMBER(D16),D16>=3),AND(ISNUMBER(D18),D18>=3,ISNUMBER(D19),D19>=3,ISNUMBER(D20),D20>=3,ISNUMBER(D21),D21>=3,ISNUMBER(D22),D22>=3,ISNUMBER(D23),D23>=3),AND(ISNUMBER(D25),D25>=3,ISNUMBER(D26),D26>=3,ISNUMBER(D27),D27>=3)),"Tier 2: Intermediate",IF(AND(AND(ISNUMBER(D13),D13>=3,ISNUMBER(D14),D14>=3,ISNUMBER(D15),D15>=3,ISNUMBER(D16),D16>=3),AND(ISNUMBER(D18),D18>=3,ISNUMBER(D19),D19>=3,ISNUMBER(D20),D20>=3,ISNUMBER(D21),D21>=3,ISNUMBER(D22),D22>=3,ISNUMBER(D23),D23>=3)),"Tier 1: Basic",IF(AND(AND(ISNUMBER(D13),D13>=3,ISNUMBER(D14),D14>=3,ISNUMBER(D15),D15>=3,ISNUMBER(D16),D16>=3)),"Tier 0: Foundation","Below Foundation"))))) | F6: =COUNTA(Assessment!E15,Assessment!E16,Assessment!E17,Assessment!E18,Assessment!E19,Assessment!E20,Assessment!E21,Assessment!E24,Assessment!E25,Assessment!E26,Assessment!E27,Assessment!E28,Assessment!E29,Assessment!E30,Assessment!E31,Assessment!E32,Assessment!E35,Assessment!E36,Assessment!E37,Assessment!E38,Assessment!E39,Assessment!E40,Assessment!E43,Assessment!E44,Assessment!E45,Assessment!E46,Assessment!E47,Assessment!E50,Assessment!E51,Assessment!E52,Assessment!E53,Assessment!E54,Assessment!E61,Assessment!E62,Assessment!E63,Assessment!E64,Assessment!E65,Assessment!E68,Assessment!E69,Assessment!E70,Assessment!E71)&" / 41"
B8: =IF(D6="","",IF(D6="Tier 4: Expert","Your organization has achieved Tier 4 (Expert)—the highest DEBMM tier. Your detection engineering program is mature across all dimensions: proactive threat hunting, automation of key lifecycle stages, and continuous improvement driven by data. Focus on sustaining this level and contributing to the broader detection engineering community.",IF(D6="Tier 3: Advanced","Your organization has achieved Tier 3 (Advanced). You have a highly capable detection program with systematic FN reduction, external validation, and behavioral detection of advanced TTPs. To reach Tier 4, develop proactive threat hunting capabilities, adopt hypothesis-driven hunting workflows, and integrate automation and AI across the detection lifecycle.",IF(D6="Tier 2: Intermediate","Your organization has achieved Tier 2 (Intermediate). Your detection program has mature processes for rule development, telemetry management, false positive reduction, and gap analysis. To advance to Tier 3, invest in false negative triage, external validation (e.g., purple team exercises), and coverage of advanced TTPs.",IF(D6="Tier 1: Basic","Your organization has achieved Tier 1 (Basic). You have solid foundations and basic detection capabilities in place, including baseline rules, telemetry coverage, and release testing at the Defined level. To advance to Tier 2, focus on systematic false positive reduction, formal gap analysis, and internal testing and validation.",IF(D6="Tier 0: Foundation","Your organization has achieved Tier 0 (Foundation). All foundational criteria meet the Defined level, meaning you have documented processes for rule development, maintenance, roadmaps, and threat modeling. To reach Tier 1, ensure your baseline rules, telemetry quality, threat landscape reviews, and release testing also reach the Defined level.","Your organization has not yet achieved Tier 0 (Foundation). This means one or more foundational criteria—such as structured rule development, rule maintenance, roadmap documentation, or threat modeling—score below the Defined level (3.0). Focus on establishing basic, repeatable processes in these areas before advancing to higher tiers."))))))
B10: DEBMM CORE ASSESSMENT
C11: Category / Criterion | D11: Score | E11: Level | F11: Status
C12: Foundation | D12: =IF(COUNT(D13,D14,D15,D16)=0,"",AVERAGE(D13,D14,D15,D16)) | E12: =IF(D12="","",IF(D12>=4.5,"Optimized",IF(D12>=3.5,"Managed",IF(D12>=2.5,"Defined",IF(D12>=1.5,"Repeatable","Initial"))))) | F12: =IF(D12="","",IF(D12>=3,"✓ Pass","✗ Below Target"))
C13: Structured Rule Development Approach | D13: =IF(COUNT(Assessment!F15,Assessment!F16)=0,"",AVERAGE(Assessment!F15,Assessment!F16)) | E13: =IF(D13="","",IF(D13>=4.5,"Optimized",IF(D13>=3.5,"Managed",IF(D13>=2.5,"Defined",IF(D13>=1.5,"Repeatable","Initial"))))) | F13: =IF(D13="","",IF(D13>=3,"✓ Pass","✗ Below Target"))
C14: Rule Creation and Maintenance | D14: =IF(COUNT(Assessment!F17)=0,"",AVERAGE(Assessment!F17)) | E14: =IF(D14="","",IF(D14>=4.5,"Optimized",IF(D14>=3.5,"Managed",IF(D14>=2.5,"Defined",IF(D14>=1.5,"Repeatable","Initial"))))) | F14: =IF(D14="","",IF(D14>=3,"✓ Pass","✗ Below Target"))
C15: Roadmap Documentation | D15: =IF(COUNT(Assessment!F18)=0,"",AVERAGE(Assessment!F18)) | E15: =IF(D15="","",IF(D15>=4.5,"Optimized",IF(D15>=3.5,"Managed",IF(D15>=2.5,"Defined",IF(D15>=1.5,"Repeatable","Initial"))))) | F15: =IF(D15="","",IF(D15>=3,"✓ Pass","✗ Below Target"))
C16: Threat Modeling | D16: =IF(COUNT(Assessment!F19,Assessment!F20,Assessment!F21)=0,"",AVERAGE(Assessment!F19,Assessment!F20,Assessment!F21)) | E16: =IF(D16="","",IF(D16>=4.5,"Optimized",IF(D16>=3.5,"Managed",IF(D16>=2.5,"Defined",IF(D16>=1.5,"Repeatable","Initial"))))) | F16: =IF(D16="","",IF(D16>=3,"✓ Pass","✗ Below Target"))
C17: Basic | D17: =IF(COUNT(D18,D19,D20,D21,D22,D23)=0,"",AVERAGE(D18,D19,D20,D21,D22,D23)) | E17: =IF(D17="","",IF(D17>=4.5,"Optimized",IF(D17>=3.5,"Managed",IF(D17>=2.5,"Defined",IF(D17>=1.5,"Repeatable","Initial"))))) | F17: =IF(D17="","",IF(D17>=3,"✓ Pass","✗ Below Target"))
C18: Baseline Rule Creation | D18: =IF(COUNT(Assessment!F24,Assessment!F25)=0,"",AVERAGE(Assessment!F24,Assessment!F25)) | E18: =IF(D18="","",IF(D18>=4.5,"Optimized",IF(D18>=3.5,"Managed",IF(D18>=2.5,"Defined",IF(D18>=1.5,"Repeatable","Initial"))))) | F18: =IF(D18="","",IF(D18>=3,"✓ Pass","✗ Below Target"))
C19: Ruleset Management and Maintenance | D19: =IF(COUNT(Assessment!F26)=0,"",AVERAGE(Assessment!F26)) | E19: =IF(D19="","",IF(D19>=4.5,"Optimized",IF(D19>=3.5,"Managed",IF(D19>=2.5,"Defined",IF(D19>=1.5,"Repeatable","Initial"))))) | F19: =IF(D19="","",IF(D19>=3,"✓ Pass","✗ Below Target"))
C20: Telemetry Quality | D20: =IF(COUNT(Assessment!F27,Assessment!F28,Assessment!F29)=0,"",AVERAGE(Assessment!F27,Assessment!F28,Assessment!F29)) | E20: =IF(D20="","",IF(D20>=4.5,"Optimized",IF(D20>=3.5,"Managed",IF(D20>=2.5,"Defined",IF(D20>=1.5,"Repeatable","Initial"))))) | F20: =IF(D20="","",IF(D20>=3,"✓ Pass","✗ Below Target"))
C21: Threat Landscape Review | D21: =IF(COUNT(Assessment!F30)=0,"",AVERAGE(Assessment!F30)) | E21: =IF(D21="","",IF(D21>=4.5,"Optimized",IF(D21>=3.5,"Managed",IF(D21>=2.5,"Defined",IF(D21>=1.5,"Repeatable","Initial"))))) | F21: =IF(D21="","",IF(D21>=3,"✓ Pass","✗ Below Target"))
C22: Product Owner Engagement | D22: =IF(COUNT(Assessment!F31)=0,"",AVERAGE(Assessment!F31)) | E22: =IF(D22="","",IF(D22>=4.5,"Optimized",IF(D22>=3.5,"Managed",IF(D22>=2.5,"Defined",IF(D22>=1.5,"Repeatable","Initial"))))) | F22: =IF(D22="","",IF(D22>=3,"✓ Pass","✗ Below Target"))
C23: Release Testing and Validation | D23: =IF(COUNT(Assessment!F32)=0,"",AVERAGE(Assessment!F32)) | E23: =IF(D23="","",IF(D23>=4.5,"Optimized",IF(D23>=3.5,"Managed",IF(D23>=2.5,"Defined",IF(D23>=1.5,"Repeatable","Initial"))))) | F23: =IF(D23="","",IF(D23>=3,"✓ Pass","✗ Below Target"))
C24: Intermediate | D24: =IF(COUNT(D25,D26,D27)=0,"",AVERAGE(D25,D26,D27)) | E24: =IF(D24="","",IF(D24>=4.5,"Optimized",IF(D24>=3.5,"Managed",IF(D24>=2.5,"Defined",IF(D24>=1.5,"Repeatable","Initial"))))) | F24: =IF(D24="","",IF(D24>=3,"✓ Pass","✗ Below Target"))
C25: False Positive Tuning and Reduction | D25: =IF(COUNT(Assessment!F35,Assessment!F36)=0,"",AVERAGE(Assessment!F35,Assessment!F36)) | E25: =IF(D25="","",IF(D25>=4.5,"Optimized",IF(D25>=3.5,"Managed",IF(D25>=2.5,"Defined",IF(D25>=1.5,"Repeatable","Initial"))))) | F25: =IF(D25="","",IF(D25>=3,"✓ Pass","✗ Below Target"))
C26: Gap Analysis and Documentation | D26: =IF(COUNT(Assessment!F37,Assessment!F38,Assessment!F39)=0,"",AVERAGE(Assessment!F37,Assessment!F38,Assessment!F39)) | E26: =IF(D26="","",IF(D26>=4.5,"Optimized",IF(D26>=3.5,"Managed",IF(D26>=2.5,"Defined",IF(D26>=1.5,"Repeatable","Initial"))))) | F26: =IF(D26="","",IF(D26>=3,"✓ Pass","✗ Below Target"))
C27: Internal Testing and Validation | D27: =IF(COUNT(Assessment!F40)=0,"",AVERAGE(Assessment!F40)) | E27: =IF(D27="","",IF(D27>=4.5,"Optimized",IF(D27>=3.5,"Managed",IF(D27>=2.5,"Defined",IF(D27>=1.5,"Repeatable","Initial"))))) | F27: =IF(D27="","",IF(D27>=3,"✓ Pass","✗ Below Target"))
C28: Advanced | D28: =IF(COUNT(D29,D30,D31)=0,"",AVERAGE(D29,D30,D31)) | E28: =IF(D28="","",IF(D28>=4.5,"Optimized",IF(D28>=3.5,"Managed",IF(D28>=2.5,"Defined",IF(D28>=1.5,"Repeatable","Initial"))))) | F28: =IF(D28="","",IF(D28>=3,"✓ Pass","✗ Below Target"))
C29: False Negative Triage | D29: =IF(COUNT(Assessment!F43,Assessment!F44)=0,"",AVERAGE(Assessment!F43,Assessment!F44)) | E29: =IF(D29="","",IF(D29>=4.5,"Optimized",IF(D29>=3.5,"Managed",IF(D29>=2.5,"Defined",IF(D29>=1.5,"Repeatable","Initial"))))) | F29: =IF(D29="","",IF(D29>=3,"✓ Pass","✗ Below Target"))
C30: External Validation | D30: =IF(COUNT(Assessment!F45)=0,"",AVERAGE(Assessment!F45)) | E30: =IF(D30="","",IF(D30>=4.5,"Optimized",IF(D30>=3.5,"Managed",IF(D30>=2.5,"Defined",IF(D30>=1.5,"Repeatable","Initial"))))) | F30: =IF(D30="","",IF(D30>=3,"✓ Pass","✗ Below Target"))
C31: Advanced TTP Coverage | D31: =IF(COUNT(Assessment!F46,Assessment!F47)=0,"",AVERAGE(Assessment!F46,Assessment!F47)) | E31: =IF(D31="","",IF(D31>=4.5,"Optimized",IF(D31>=3.5,"Managed",IF(D31>=2.5,"Defined",IF(D31>=1.5,"Repeatable","Initial"))))) | F31: =IF(D31="","",IF(D31>=3,"✓ Pass","✗ Below Target"))
C32: Expert | D32: =IF(COUNT(D33,D34)=0,"",AVERAGE(D33,D34)) | E32: =IF(D32="","",IF(D32>=4.5,"Optimized",IF(D32>=3.5,"Managed",IF(D32>=2.5,"Defined",IF(D32>=1.5,"Repeatable","Initial"))))) | F32: =IF(D32="","",IF(D32>=3,"✓ Pass","✗ Below Target"))
C33: Threat Hunting in Telemetry | D33: =IF(COUNT(Assessment!F50,Assessment!F51,Assessment!F52)=0,"",AVERAGE(Assessment!F50,Assessment!F51,Assessment!F52)) | E33: =IF(D33="","",IF(D33>=4.5,"Optimized",IF(D33>=3.5,"Managed",IF(D33>=2.5,"Defined",IF(D33>=1.5,"Repeatable","Initial"))))) | F33: =IF(D33="","",IF(D33>=3,"✓ Pass","✗ Below Target"))
C34: Automation and Continuous Improvement | D34: =IF(COUNT(Assessment!F53,Assessment!F54)=0,"",AVERAGE(Assessment!F53,Assessment!F54)) | E34: =IF(D34="","",IF(D34>=4.5,"Optimized",IF(D34>=3.5,"Managed",IF(D34>=2.5,"Defined",IF(D34>=1.5,"Repeatable","Initial"))))) | F34: =IF(D34="","",IF(D34>=3,"✓ Pass","✗ Below Target"))
B36: SUPPLEMENTARY DIMENSIONS
B37: Organizational readiness factors — do not affect DEBMM tier determination
C38: Category / Criterion | D38: Score | E38: Level | F38: Status
C39: People & Organization | D39: =IF(COUNT(D40,D41,D42)=0,"",AVERAGE(D40,D41,D42)) | E39: =IF(D39="","",IF(D39>=4.5,"Optimized",IF(D39>=3.5,"Managed",IF(D39>=2.5,"Defined",IF(D39>=1.5,"Repeatable","Initial"))))) | F39: =IF(D39="","",IF(D39>=3,"✓ Pass","✗ Below Target"))
C40: Team Structure and Dedicated Roles | D40: =IF(COUNT(Assessment!F61)=0,"",AVERAGE(Assessment!F61)) | E40: =IF(D40="","",IF(D40>=4.5,"Optimized",IF(D40>=3.5,"Managed",IF(D40>=2.5,"Defined",IF(D40>=1.5,"Repeatable","Initial"))))) | F40: =IF(D40="","",IF(D40>=3,"✓ Pass","✗ Below Target"))
C41: Skills Development and Training | D41: =IF(COUNT(Assessment!F62)=0,"",AVERAGE(Assessment!F62)) | E41: =IF(D41="","",IF(D41>=4.5,"Optimized",IF(D41>=3.5,"Managed",IF(D41>=2.5,"Defined",IF(D41>=1.5,"Repeatable","Initial"))))) | F41: =IF(D41="","",IF(D41>=3,"✓ Pass","✗ Below Target"))
C42: Leadership Commitment and Executive Sponsorship | D42: =IF(COUNT(Assessment!F63,Assessment!F64,Assessment!F65)=0,"",AVERAGE(Assessment!F63,Assessment!F64,Assessment!F65)) | E42: =IF(D42="","",IF(D42>=4.5,"Optimized",IF(D42>=3.5,"Managed",IF(D42>=2.5,"Defined",IF(D42>=1.5,"Repeatable","Initial"))))) | F42: =IF(D42="","",IF(D42>=3,"✓ Pass","✗ Below Target"))
C43: Process & Governance | D43: =IF(COUNT(D44,D45,D46)=0,"",AVERAGE(D44,D45,D46)) | E43: =IF(D43="","",IF(D43>=4.5,"Optimized",IF(D43>=3.5,"Managed",IF(D43>=2.5,"Defined",IF(D43>=1.5,"Repeatable","Initial"))))) | F43: =IF(D43="","",IF(D43>=3,"✓ Pass","✗ Below Target"))
C44: Detection Lifecycle Workflow | D44: =IF(COUNT(Assessment!F68)=0,"",AVERAGE(Assessment!F68)) | E44: =IF(D44="","",IF(D44>=4.5,"Optimized",IF(D44>=3.5,"Managed",IF(D44>=2.5,"Defined",IF(D44>=1.5,"Repeatable","Initial"))))) | F44: =IF(D44="","",IF(D44>=3,"✓ Pass","✗ Below Target"))
C45: Metrics and KPI Tracking | D45: =IF(COUNT(Assessment!F69,Assessment!F70)=0,"",AVERAGE(Assessment!F69,Assessment!F70)) | E45: =IF(D45="","",IF(D45>=4.5,"Optimized",IF(D45>=3.5,"Managed",IF(D45>=2.5,"Defined",IF(D45>=1.5,"Repeatable","Initial"))))) | F45: =IF(D45="","",IF(D45>=3,"✓ Pass","✗ Below Target"))
...

Sheet Tier Scores Chart
A1: DEBMM Tier Scores
A2: Average score per DEBMM core tier (target: 3.0)
B4: Tier | C4: Score
B5: Foundation | C5: ='Results Dashboard'!D12
B6: Basic | C6: ='Results Dashboard'!D17
B7: Intermediate | C7: ='Results Dashboard'!D24
B8: Advanced | C8: ='Results Dashboard'!D28
B9: Expert | C9: ='Results Dashboard'!D32

Sheet Readiness Chart
A1: Organizational Readiness
A2: Supplementary dimensions — do not affect DEBMM tier determination
B4: Dimension | C4: Score
B5: People & Organization | C5: ='Results Dashboard'!D39
B6: Process & Governance | C6: ='Results Dashboard'!D43

Sheet Rubric Reference
A1: DEBMM Rubric Reference
A3: DEBMM CORE TIERS
A4: Tier 0: Foundation
A5: Establishes the basic groundwork for detection engineering. Without these foundational practices, higher-tier activities lack structure and consistency.
A6: Structured Rule Development Approach
A7: Level | B7: Description | C7: Quantitative Measure
A8: 1 — Initial | B8: No structured approach to rule development. Rules are created randomly or reactively without any guiding methodology. | C8: 0% of rules follow a formal development process.
A9: 2 — Repeatable | B9: Some rules follow a loose process, but it is inconsistently applied. Individual contributors may have personal workflows. | C9: <30% of rules follow a documented development process.
A10: 3 — Defined | B10: A defined rule development methodology exists and is documented. Most new rules follow the standard process including peer review. | C10: 50-70% of rules follow the documented process; schema alignment >60%.
A11: 4 — Managed | B11: Rule development is standardized across the team with enforced workflows, templates, and quality gates. Deviations are tracked and addressed. | C11: 80-90% schema alignment; all new rules go through formal review.
A12: 5 — Optimized | B12: Continuous improvement of the development process based on feedback loops. Process is fully integrated with CI/CD and automated quality checks. | C12: 90-100% schema alignment; automated linting and validation on all rules.
A14: Rule Creation and Maintenance
A15: Level | B15: Description | C15: Quantitative Measure
A16: 1 — Initial | B16: Rules are created ad hoc with no maintenance schedule. Stale or broken rules accumulate over time. | C16: <50% of rules reviewed annually.
A17: 2 — Repeatable | B17: Some rules are periodically reviewed, but there is no systematic maintenance process. Updates happen reactively. | C17: 50-70% of rules reviewed annually; no formal peer review.
A18: 3 — Defined | B18: Regular rule review cycles are established. Rules have owners and defined review schedules. Peer review is standard practice. | C18: 70-80% of rules reviewed on schedule; peer review on most changes.
A19: 4 — Managed | B19: Comprehensive rule lifecycle management with creation, testing, deployment, monitoring, and retirement processes. All changes are peer-reviewed. | C19: 80-90% of rules reviewed on schedule; 100% peer review on changes.
A20: 5 — Optimized | B20: Continuous rule improvement with automated monitoring of rule health. Automated updates triggered by telemetry changes or threat intelligence. | C20: 90-100% of rules reviewed on schedule; automated health monitoring.
A22: Roadmap Documentation
A23: Level | B23: Description | C23: Quantitative Measure
A24: 1 — Initial | B24: No detection roadmap exists. Work is entirely reactive or driven by individual initiative. | C24: 0% of detection work tied to a documented plan.
A25: 2 — Repeatable | B25: An informal roadmap or backlog exists but is not regularly maintained or communicated to stakeholders. | C25: <30% of rules have scheduled review or development timelines.
A26: 3 — Defined | B26: A formal roadmap is documented, reviewed quarterly, and shared with relevant stakeholders. Priorities are clear. | C26: 50-70% of planned work is tracked against the roadmap.
A27: 4 — Managed | B27: Roadmap is integrated with organizational security strategy. Progress is tracked with metrics and reported to leadership. | C27: 70-90% of planned work tracked; quarterly roadmap reviews with leadership.
A28: 5 — Optimized | B28: Dynamic, continuously updated roadmap driven by threat intelligence, gap analysis, and organizational risk priorities. | C28: 90-100% of work tracked; roadmap auto-updated from gap analysis and intel feeds.
A30: Threat Modeling
A31: Level | B31: Description | C31: Quantitative Measure
A32: 1 — Initial | B32: No threat modeling is performed. Detection rules are not informed by a structured understanding of threats to the organization. | C32: Zero threat modeling exercises performed.
A33: 2 — Repeatable | B33: Occasional threat modeling exercises, typically triggered by incidents or major changes. Not regularly scheduled. | C33: <1 formal threat modeling exercise per year.
A34: 3 — Defined | B34: Regular threat modeling exercises (at least quarterly) inform detection priorities. Results are documented and fed into the roadmap. | C34: Quarterly threat modeling exercises; results documented.
A35: 4 — Managed | B35: Threat modeling is integrated into the detection development lifecycle. New detections are prioritized based on threat model outputs. | C35: Monthly exercises; >70% of new detections tied to threat model outputs.
A36: 5 — Optimized | B36: Continuous, proactive threat modeling incorporating real-time threat intelligence, attack surface changes, and emerging TTPs. | C36: Continuous modeling; real-time integration with threat intel feeds.
A38: Tier 1: Basic
A39: Establishes baseline detection capabilities with systematic management, version control, and initial alignment with the threat landscape.
A40: Baseline Rule Creation
A41: Level | B41: Description | C41: Quantitative Measure
A42: 1 — Initial | B42: Few or no baseline detection rules exist. Coverage is minimal and limited to out-of-the-box vendor rules. | C42: <10 custom baseline rules; minimal ATT&CK technique coverage.
A43: 2 — Repeatable | B43: A small set of baseline rules covers the most critical threats. Rules are basic signature or IOC-based detections. | C43: 10-30 baseline rules; <30% ATT&CK technique coverage for priority areas.
A44: 3 — Defined | B44: Baseline rules cover key threat categories with a mix of signature and behavioral detections. Coverage gaps are identified. | C44: 30-60 baseline rules; 30-50% ATT&CK technique coverage with documented gaps.
A45: 4 — Managed | B45: Comprehensive baseline with behavioral and TTP-focused detections. Rules are tuned per environment and regularly validated. | C45: 60-100 baseline rules; 50-70% ATT&CK technique coverage including behavioral detections; gaps tracked against threat model.
...

Sheet Report Data
A1: SUMMARY
A2: Organization | B2: =Assessment!D4
A3: Assessor | B3: =Assessment!D5
A4: Date | B4: =Assessment!D7
A5: Assessment Type | B5: =Assessment!D8
A6: Overall Score | B6: =IF(COUNT(D18,D19,D20,D21,D22,D23,D24,D25,D26,D27,D28,D29,D30,D31,D32,D33,D34,D35,D36,D37,D38,D39,D40,D41)=0,"",ROUND(AVERAGE(D18,D19,D20,D21,D22,D23,D24,D25,D26,D27,D28,D29,D30,D31,D32,D33,D34,D35,D36,D37,D38,D39,D40,D41),2))
A7: Achieved Tier | B7: =IF(AND(AND(ISNUMBER(D18),D18>=3,ISNUMBER(D19),D19>=3,ISNUMBER(D20),D20>=3,ISNUMBER(D21),D21>=3),AND(ISNUMBER(D22),D22>=3,ISNUMBER(D23),D23>=3,ISNUMBER(D24),D24>=3,ISNUMBER(D25),D25>=3,ISNUMBER(D26),D26>=3,ISNUMBER(D27),D27>=3),AND(ISNUMBER(D28),D28>=3,ISNUMBER(D29),D29>=3,ISNUMBER(D30),D30>=3),AND(ISNUMBER(D31),D31>=3,ISNUMBER(D32),D32>=3,ISNUMBER(D33),D33>=3),AND(ISNUMBER(D34),D34>=3,ISNUMBER(D35),D35>=3)),"Tier 4: Expert",IF(AND(AND(ISNUMBER(D18),D18>=3,ISNUMBER(D19),D19>=3,ISNUMBER(D20),D20>=3,ISNUMBER(D21),D21>=3),AND(ISNUMBER(D22),D22>=3,ISNUMBER(D23),D23>=3,ISNUMBER(D24),D24>=3,ISNUMBER(D25),D25>=3,ISNUMBER(D26),D26>=3,ISNUMBER(D27),D27>=3),AND(ISNUMBER(D28),D28>=3,ISNUMBER(D29),D29>=3,ISNUMBER(D30),D30>=3),AND(ISNUMBER(D31),D31>=3,ISNUMBER(D32),D32>=3,ISNUMBER(D33),D33>=3)),"Tier 3: Advanced",IF(AND(AND(ISNUMBER(D18),D18>=3,ISNUMBER(D19),D19>=3,ISNUMBER(D20),D20>=3,ISNUMBER(D21),D21>=3),AND(ISNUMBER(D22),D22>=3,ISNUMBER(D23),D23>=3,ISNUMBER(D24),D24>=3,ISNUMBER(D25),D25>=3,ISNUMBER(D26),D26>=3,ISNUMBER(D27),D27>=3),AND(ISNUMBER(D28),D28>=3,ISNUMBER(D29),D29>=3,ISNUMBER(D30),D30>=3)),"Tier 2: Intermediate",IF(AND(AND(ISNUMBER(D18),D18>=3,ISNUMBER(D19),D19>=3,ISNUMBER(D20),D20>=3,ISNUMBER(D21),D21>=3),AND(ISNUMBER(D22),D22>=3,ISNUMBER(D23),D23>=3,ISNUMBER(D24),D24>=3,ISNUMBER(D25),D25>=3,ISNUMBER(D26),D26>=3,ISNUMBER(D27),D27>=3)),"Tier 1: Basic",IF(AND(AND(ISNUMBER(D18),D18>=3,ISNUMBER(D19),D19>=3,ISNUMBER(D20),D20>=3,ISNUMBER(D21),D21>=3)),"Tier 0: Foundation","Below Foundation")))))
A8: Completion | B8: =COUNTA(Assessment!E15,Assessment!E16,Assessment!E17,Assessment!E18,Assessment!E19,Assessment!E20,Assessment!E21,Assessment!E24,Assessment!E25,Assessment!E26,Assessment!E27,Assessment!E28,Assessment!E29,Assessment!E30,Assessment!E31,Assessment!E32,Assessment!E35,Assessment!E36,Assessment!E37,Assessment!E38,Assessment!E39,Assessment!E40,Assessment!E43,Assessment!E44,Assessment!E45,Assessment!E46,Assessment!E47,Assessment!E50,Assessment!E51,Assessment!E52,Assessment!E53,Assessment!E54,Assessment!E61,Assessment!E62,Assessment!E63,Assessment!E64,Assessment!E65,Assessment!E68,Assessment!E69,Assessment!E70,Assessment!E71)&" / 41"
A10: Tier | B10: Tier Name | C10: Score | D10: Level | E10: Status | F10: Progression
A11: T0 | B11: Foundation | C11: =IF(COUNT(Assessment!F15,Assessment!F16,Assessment!F17,Assessment!F18,Assessment!F19,Assessment!F20,Assessment!F21)=0,"",AVERAGE(Assessment!F15,Assessment!F16,Assessment!F17,Assessment!F18,Assessment!F19,Assessment!F20,Assessment!F21)) | D11: =IF(C11="","",IF(C11>=4.5,"Optimized",IF(C11>=3.5,"Managed",IF(C11>=2.5,"Defined",IF(C11>=1.5,"Repeatable","Initial"))))) | E11: =IF(C11="","",IF(C11>=3,"✓ Pass","✗ Below Target")) | F11: =IF(C11="","Not Started",IF(AND(AND(ISNUMBER(D18),D18>=3,ISNUMBER(D19),D19>=3,ISNUMBER(D20),D20>=3,ISNUMBER(D21),D21>=3)),"Complete",IF(TRUE,"Current","In Progress")))
A12: T1 | B12: Basic | C12: =IF(COUNT(Assessment!F24,Assessment!F25,Assessment!F26,Assessment!F27,Assessment!F28,Assessment!F29,Assessment!F30,Assessment!F31,Assessment!F32)=0,"",AVERAGE(Assessment!F24,Assessment!F25,Assessment!F26,Assessment!F27,Assessment!F28,Assessment!F29,Assessment!F30,Assessment!F31,Assessment!F32)) | D12: =IF(C12="","",IF(C12>=4.5,"Optimized",IF(C12>=3.5,"Managed",IF(C12>=2.5,"Defined",IF(C12>=1.5,"Repeatable","Initial"))))) | E12: =IF(C12="","",IF(C12>=3,"✓ Pass","✗ Below Target")) | F12: =IF(C12="","Not Started",IF(AND(AND(ISNUMBER(D18),D18>=3,ISNUMBER(D19),D19>=3,ISNUMBER(D20),D20>=3,ISNUMBER(D21),D21>=3),AND(ISNUMBER(D22),D22>=3,ISNUMBER(D23),D23>=3,ISNUMBER(D24),D24>=3,ISNUMBER(D25),D25>=3,ISNUMBER(D26),D26>=3,ISNUMBER(D27),D27>=3)),"Complete",IF(AND(AND(ISNUMBER(D18),D18>=3,ISNUMBER(D19),D19>=3,ISNUMBER(D20),D20>=3,ISNUMBER(D21),D21>=3)),"Current","In Progress")))
A13: T2 | B13: Intermediate | C13: =IF(COUNT(Assessment!F35,Assessment!F36,Assessment!F37,Assessment!F38,Assessment!F39,Assessment!F40)=0,"",AVERAGE(Assessment!F35,Assessment!F36,Assessment!F37,Assessment!F38,Assessment!F39,Assessment!F40)) | D13: =IF(C13="","",IF(C13>=4.5,"Optimized",IF(C13>=3.5,"Managed",IF(C13>=2.5,"Defined",IF(C13>=1.5,"Repeatable","Initial"))))) | E13: =IF(C13="","",IF(C13>=3,"✓ Pass","✗ Below Target")) | F13: =IF(C13="","Not Started",IF(AND(AND(ISNUMBER(D18),D18>=3,ISNUMBER(D19),D19>=3,ISNUMBER(D20),D20>=3,ISNUMBER(D21),D21>=3),AND(ISNUMBER(D22),D22>=3,ISNUMBER(D23),D23>=3,ISNUMBER(D24),D24>=3,ISNUMBER(D25),D25>=3,ISNUMBER(D26),D26>=3,ISNUMBER(D27),D27>=3),AND(ISNUMBER(D28),D28>=3,ISNUMBER(D29),D29>=3,ISNUMBER(D30),D30>=3)),"Complete",IF(AND(AND(ISNUMBER(D18),D18>=3,ISNUMBER(D19),D19>=3,ISNUMBER(D20),D20>=3,ISNUMBER(D21),D21>=3),AND(ISNUMBER(D22),D22>=3,ISNUMBER(D23),D23>=3,ISNUMBER(D24),D24>=3,ISNUMBER(D25),D25>=3,ISNUMBER(D26),D26>=3,ISNUMBER(D27),D27>=3)),"Current","In Progress")))
A14: T3 | B14: Advanced | C14: =IF(COUNT(Assessment!F43,Assessment!F44,Assessment!F45,Assessment!F46,Assessment!F47)=0,"",AVERAGE(Assessment!F43,Assessment!F44,Assessment!F45,Assessment!F46,Assessment!F47)) | D14: =IF(C14="","",IF(C14>=4.5,"Optimized",IF(C14>=3.5,"Managed",IF(C14>=2.5,"Defined",IF(C14>=1.5,"Repeatable","Initial"))))) | E14: =IF(C14="","",IF(C14>=3,"✓ Pass","✗ Below Target")) | F14: =IF(C14="","Not Started",IF(AND(AND(ISNUMBER(D18),D18>=3,ISNUMBER(D19),D19>=3,ISNUMBER(D20),D20>=3,ISNUMBER(D21),D21>=3),AND(ISNUMBER(D22),D22>=3,ISNUMBER(D23),D23>=3,ISNUMBER(D24),D24>=3,ISNUMBER(D25),D25>=3,ISNUMBER(D26),D26>=3,ISNUMBER(D27),D27>=3),AND(ISNUMBER(D28),D28>=3,ISNUMBER(D29),D29>=3,ISNUMBER(D30),D30>=3),AND(ISNUMBER(D31),D31>=3,ISNUMBER(D32),D32>=3,ISNUMBER(D33),D33>=3)),"Complete",IF(AND(AND(ISNUMBER(D18),D18>=3,ISNUMBER(D19),D19>=3,ISNUMBER(D20),D20>=3,ISNUMBER(D21),D21>=3),AND(ISNUMBER(D22),D22>=3,ISNUMBER(D23),D23>=3,ISNUMBER(D24),D24>=3,ISNUMBER(D25),D25>=3,ISNUMBER(D26),D26>=3,ISNUMBER(D27),D27>=3),AND(ISNUMBER(D28),D28>=3,ISNUMBER(D29),D29>=3,ISNUMBER(D30),D30>=3)),"Current","In Progress")))
A15: T4 | B15: Expert | C15: =IF(COUNT(Assessment!F50,Assessment!F51,Assessment!F52,Assessment!F53,Assessment!F54)=0,"",AVERAGE(Assessment!F50,Assessment!F51,Assessment!F52,Assessment!F53,Assessment!F54)) | D15: =IF(C15="","",IF(C15>=4.5,"Optimized",IF(C15>=3.5,"Managed",IF(C15>=2.5,"Defined",IF(C15>=1.5,"Repeatable","Initial"))))) | E15: =IF(C15="","",IF(C15>=3,"✓ Pass","✗ Below Target")) | F15: =IF(C15="","Not Started",IF(AND(AND(ISNUMBER(D18),D18>=3,ISNUMBER(D19),D19>=3,ISNUMBER(D20),D20>=3,ISNUMBER(D21),D21>=3),AND(ISNUMBER(D22),D22>=3,ISNUMBER(D23),D23>=3,ISNUMBER(D24),D24>=3,ISNUMBER(D25),D25>=3,ISNUMBER(D26),D26>=3,ISNUMBER(D27),D27>=3),AND(ISNUMBER(D28),D28>=3,ISNUMBER(D29),D29>=3,ISNUMBER(D30),D30>=3),AND(ISNUMBER(D31),D31>=3,ISNUMBER(D32),D32>=3,ISNUMBER(D33),D33>=3),AND(ISNUMBER(D34),D34>=3,ISNUMBER(D35),D35>=3)),"Complete",IF(AND(AND(ISNUMBER(D18),D18>=3,ISNUMBER(D19),D19>=3,ISNUMBER(D20),D20>=3,ISNUMBER(D21),D21>=3),AND(ISNUMBER(D22),D22>=3,ISNUMBER(D23),D23>=3,ISNUMBER(D24),D24>=3,ISNUMBER(D25),D25>=3,ISNUMBER(D26),D26>=3,ISNUMBER(D27),D27>=3),AND(ISNUMBER(D28),D28>=3,ISNUMBER(D29),D29>=3,ISNUMBER(D30),D30>=3),AND(ISNUMBER(D31),D31>=3,ISNUMBER(D32),D32>=3,ISNUMBER(D33),D33>=3)),"Current","In Progress")))
A17: Section | B17: Category | C17: Criterion | D17: Score | E17: Level | F17: Status
A18: DEBMM Core | B18: Foundation | C18: Structured Rule Development Approach | D18: =IF(COUNT(Assessment!F15,Assessment!F16)=0,"",AVERAGE(Assessment!F15,Assessment!F16)) | E18: =IF(D18="","",IF(D18>=4.5,"Optimized",IF(D18>=3.5,"Managed",IF(D18>=2.5,"Defined",IF(D18>=1.5,"Repeatable","Initial"))))) | F18: =IF(D18="","",IF(D18>=3,"✓ Pass","✗ Below Target"))
A19: DEBMM Core | B19: Foundation | C19: Rule Creation and Maintenance | D19: =IF(COUNT(Assessment!F17)=0,"",AVERAGE(Assessment!F17)) | E19: =IF(D19="","",IF(D19>=4.5,"Optimized",IF(D19>=3.5,"Managed",IF(D19>=2.5,"Defined",IF(D19>=1.5,"Repeatable","Initial"))))) | F19: =IF(D19="","",IF(D19>=3,"✓ Pass","✗ Below Target"))
A20: DEBMM Core | B20: Foundation | C20: Roadmap Documentation | D20: =IF(COUNT(Assessment!F18)=0,"",AVERAGE(Assessment!F18)) | E20: =IF(D20="","",IF(D20>=4.5,"Optimized",IF(D20>=3.5,"Managed",IF(D20>=2.5,"Defined",IF(D20>=1.5,"Repeatable","Initial"))))) | F20: =IF(D20="","",IF(D20>=3,"✓ Pass","✗ Below Target"))
A21: DEBMM Core | B21: Foundation | C21: Threat Modeling | D21: =IF(COUNT(Assessment!F19,Assessment!F20,Assessment!F21)=0,"",AVERAGE(Assessment!F19,Assessment!F20,Assessment!F21)) | E21: =IF(D21="","",IF(D21>=4.5,"Optimized",IF(D21>=3.5,"Managed",IF(D21>=2.5,"Defined",IF(D21>=1.5,"Repeatable","Initial"))))) | F21: =IF(D21="","",IF(D21>=3,"✓ Pass","✗ Below Target"))
A22: DEBMM Core | B22: Basic | C22: Baseline Rule Creation | D22: =IF(COUNT(Assessment!F24,Assessment!F25)=0,"",AVERAGE(Assessment!F24,Assessment!F25)) | E22: =IF(D22="","",IF(D22>=4.5,"Optimized",IF(D22>=3.5,"Managed",IF(D22>=2.5,"Defined",IF(D22>=1.5,"Repeatable","Initial"))))) | F22: =IF(D22="","",IF(D22>=3,"✓ Pass","✗ Below Target"))
A23: DEBMM Core | B23: Basic | C23: Ruleset Management and Maintenance | D23: =IF(COUNT(Assessment!F26)=0,"",AVERAGE(Assessment!F26)) | E23: =IF(D23="","",IF(D23>=4.5,"Optimized",IF(D23>=3.5,"Managed",IF(D23>=2.5,"Defined",IF(D23>=1.5,"Repeatable","Initial"))))) | F23: =IF(D23="","",IF(D23>=3,"✓ Pass","✗ Below Target"))
A24: DEBMM Core | B24: Basic | C24: Telemetry Quality | D24: =IF(COUNT(Assessment!F27,Assessment!F28,Assessment!F29)=0,"",AVERAGE(Assessment!F27,Assessment!F28,Assessment!F29)) | E24: =IF(D24="","",IF(D24>=4.5,"Optimized",IF(D24>=3.5,"Managed",IF(D24>=2.5,"Defined",IF(D24>=1.5,"Repeatable","Initial"))))) | F24: =IF(D24="","",IF(D24>=3,"✓ Pass","✗ Below Target"))
A25: DEBMM Core | B25: Basic | C25: Threat Landscape Review | D25: =IF(COUNT(Assessment!F30)=0,"",AVERAGE(Assessment!F30)) | E25: =IF(D25="","",IF(D25>=4.5,"Optimized",IF(D25>=3.5,"Managed",IF(D25>=2.5,"Defined",IF(D25>=1.5,"Repeatable","Initial"))))) | F25: =IF(D25="","",IF(D25>=3,"✓ Pass","✗ Below Target"))
A26: DEBMM Core | B26: Basic | C26: Product Owner Engagement | D26: =IF(COUNT(Assessment!F31)=0,"",AVERAGE(Assessment!F31)) | E26: =IF(D26="","",IF(D26>=4.5,"Optimized",IF(D26>=3.5,"Managed",IF(D26>=2.5,"Defined",IF(D26>=1.5,"Repeatable","Initial"))))) | F26: =IF(D26="","",IF(D26>=3,"✓ Pass","✗ Below Target"))
A27: DEBMM Core | B27: Basic | C27: Release Testing and Validation | D27: =IF(COUNT(Assessment!F32)=0,"",AVERAGE(Assessment!F32)) | E27: =IF(D27="","",IF(D27>=4.5,"Optimized",IF(D27>=3.5,"Managed",IF(D27>=2.5,"Defined",IF(D27>=1.5,"Repeatable","Initial"))))) | F27: =IF(D27="","",IF(D27>=3,"✓ Pass","✗ Below Target"))
A28: DEBMM Core | B28: Intermediate | C28: False Positive Tuning and Reduction | D28: =IF(COUNT(Assessment!F35,Assessment!F36)=0,"",AVERAGE(Assessment!F35,Assessment!F36)) | E28: =IF(D28="","",IF(D28>=4.5,"Optimized",IF(D28>=3.5,"Managed",IF(D28>=2.5,"Defined",IF(D28>=1.5,"Repeatable","Initial"))))) | F28: =IF(D28="","",IF(D28>=3,"✓ Pass","✗ Below Target"))
A29: DEBMM Core | B29: Intermediate | C29: Gap Analysis and Documentation | D29: =IF(COUNT(Assessment!F37,Assessment!F38,Assessment!F39)=0,"",AVERAGE(Assessment!F37,Assessment!F38,Assessment!F39)) | E29: =IF(D29="","",IF(D29>=4.5,"Optimized",IF(D29>=3.5,"Managed",IF(D29>=2.5,"Defined",IF(D29>=1.5,"Repeatable","Initial"))))) | F29: =IF(D29="","",IF(D29>=3,"✓ Pass","✗ Below Target"))
A30: DEBMM Core | B30: Intermediate | C30: Internal Testing and Validation | D30: =IF(COUNT(Assessment!F40)=0,"",AVERAGE(Assessment!F40)) | E30: =IF(D30="","",IF(D30>=4.5,"Optimized",IF(D30>=3.5,"Managed",IF(D30>=2.5,"Defined",IF(D30>=1.5,"Repeatable","Initial"))))) | F30: =IF(D30="","",IF(D30>=3,"✓ Pass","✗ Below Target"))
A31: DEBMM Core | B31: Advanced | C31: False Negative Triage | D31: =IF(COUNT(Assessment!F43,Assessment!F44)=0,"",AVERAGE(Assessment!F43,Assessment!F44)) | E31: =IF(D31="","",IF(D31>=4.5,"Optimized",IF(D31>=3.5,"Managed",IF(D31>=2.5,"Defined",IF(D31>=1.5,"Repeatable","Initial"))))) | F31: =IF(D31="","",IF(D31>=3,"✓ Pass","✗ Below Target"))
A32: DEBMM Core | B32: Advanced | C32: External Validation | D32: =IF(COUNT(Assessment!F45)=0,"",AVERAGE(Assessment!F45)) | E32: =IF(D32="","",IF(D32>=4.5,"Optimized",IF(D32>=3.5,"Managed",IF(D32>=2.5,"Defined",IF(D32>=1.5,"Repeatable","Initial"))))) | F32: =IF(D32="","",IF(D32>=3,"✓ Pass","✗ Below Target"))
A33: DEBMM Core | B33: Advanced | C33: Advanced TTP Coverage | D33: =IF(COUNT(Assessment!F46,Assessment!F47)=0,"",AVERAGE(Assessment!F46,Assessment!F47)) | E33: =IF(D33="","",IF(D33>=4.5,"Optimized",IF(D33>=3.5,"Managed",IF(D33>=2.5,"Defined",IF(D33>=1.5,"Repeatable","Initial"))))) | F33: =IF(D33="","",IF(D33>=3,"✓ Pass","✗ Below Target"))
A34: DEBMM Core | B34: Expert | C34: Threat Hunting in Telemetry | D34: =IF(COUNT(Assessment!F50,Assessment!F51,Assessment!F52)=0,"",AVERAGE(Assessment!F50,Assessment!F51,Assessment!F52)) | E34: =IF(D34="","",IF(D34>=4.5,"Optimized",IF(D34>=3.5,"Managed",IF(D34>=2.5,"Defined",IF(D34>=1.5,"Repeatable","Initial"))))) | F34: =IF(D34="","",IF(D34>=3,"✓ Pass","✗ Below Target"))
A35: DEBMM Core | B35: Expert | C35: Automation and Continuous Improvement | D35: =IF(COUNT(Assessment!F53,Assessment!F54)=0,"",AVERAGE(Assessment!F53,Assessment!F54)) | E35: =IF(D35="","",IF(D35>=4.5,"Optimized",IF(D35>=3.5,"Managed",IF(D35>=2.5,"Defined",IF(D35>=1.5,"Repeatable","Initial"))))) | F35: =IF(D35="","",IF(D35>=3,"✓ Pass","✗ Below Target"))
A36: Enrichment | B36: People & Organization | C36: Team Structure and Dedicated Roles | D36: =IF(COUNT(Assessment!F61)=0,"",AVERAGE(Assessment!F61)) | E36: =IF(D36="","",IF(D36>=4.5,"Optimized",IF(D36>=3.5,"Managed",IF(D36>=2.5,"Defined",IF(D36>=1.5,"Repeatable","Initial"))))) | F36: =IF(D36="","",IF(D36>=3,"✓ Pass","✗ Below Target"))
A37: Enrichment | B37: People & Organization | C37: Skills Development and Training | D37: =IF(COUNT(Assessment!F62)=0,"",AVERAGE(Assessment!F62)) | E37: =IF(D37="","",IF(D37>=4.5,"Optimized",IF(D37>=3.5,"Managed",IF(D37>=2.5,"Defined",IF(D37>=1.5,"Repeatable","Initial"))))) | F37: =IF(D37="","",IF(D37>=3,"✓ Pass","✗ Below Target"))
A38: Enrichment | B38: People & Organization | C38: Leadership Commitment and Executive Sponsorship | D38: =IF(COUNT(Assessment!F63,Assessment!F64,Assessment!F65)=0,"",AVERAGE(Assessment!F63,Assessment!F64,Assessment!F65)) | E38: =IF(D38="","",IF(D38>=4.5,"Optimized",IF(D38>=3.5,"Managed",IF(D38>=2.5,"Defined",IF(D38>=1.5,"Repeatable","Initial"))))) | F38: =IF(D38="","",IF(D38>=3,"✓ Pass","✗ Below Target"))
A39: Enrichment | B39: Process & Governance | C39: Detection Lifecycle Workflow | D39: =IF(COUNT(Assessment!F68)=0,"",AVERAGE(Assessment!F68)) | E39: =IF(D39="","",IF(D39>=4.5,"Optimized",IF(D39>=3.5,"Managed",IF(D39>=2.5,"Defined",IF(D39>=1.5,"Repeatable","Initial"))))) | F39: =IF(D39="","",IF(D39>=3,"✓ Pass","✗ Below Target"))
A40: Enrichment | B40: Process & Governance | C40: Metrics and KPI Tracking | D40: =IF(COUNT(Assessment!F69,Assessment!F70)=0,"",AVERAGE(Assessment!F69,Assessment!F70)) | E40: =IF(D40="","",IF(D40>=4.5,"Optimized",IF(D40>=3.5,"Managed",IF(D40>=2.5,"Defined",IF(D40>=1.5,"Repeatable","Initial"))))) | F40: =IF(D40="","",IF(D40>=3,"✓ Pass","✗ Below Target"))
A41: Enrichment | B41: Process & Governance | C41: Cross-Team Collaboration | D41: =IF(COUNT(Assessment!F71)=0,"",AVERAGE(Assessment!F71)) | E41: =IF(D41="","",IF(D41>=4.5,"Optimized",IF(D41>=3.5,"Managed",IF(D41>=2.5,"Defined",IF(D41>=1.5,"Repeatable","Initial"))))) | F41: =IF(D41="","",IF(D41>=3,"✓ Pass","✗ Below Target"))
